<?xml version="1.0" encoding="UTF-8"?>
<testng-results skipped="2" failed="1" ignored="0" total="3" passed="0">
  <reporter-output>
  </reporter-output>
  <suite name="Default suite" duration-ms="27709" started-at="2017-08-20T21:56:58Z" finished-at="2017-08-20T21:57:26Z">
    <groups>
    </groups>
    <test name="Default test" duration-ms="27709" started-at="2017-08-20T21:56:58Z" finished-at="2017-08-20T21:57:26Z">
      <class name="dataliciousAssignment.NewPhantomJsTest">
        <test-method status="PASS" signature="beforeTest()[pri:0, instance:dataliciousAssignment.NewPhantomJsTest@5383967b]" name="beforeTest" is-config="true" duration-ms="5267" started-at="2017-08-21T03:26:58Z" finished-at="2017-08-21T03:27:04Z">
          <reporter-output>
          </reporter-output>
        </test-method> <!-- beforeTest -->
        <test-method status="PASS" signature="beforeClass()[pri:0, instance:dataliciousAssignment.NewPhantomJsTest@5383967b]" name="beforeClass" is-config="true" duration-ms="1" started-at="2017-08-21T03:27:04Z" finished-at="2017-08-21T03:27:04Z">
          <reporter-output>
          </reporter-output>
        </test-method> <!-- beforeClass -->
        <test-method status="FAIL" signature="task1()[pri:0, instance:dataliciousAssignment.NewPhantomJsTest@5383967b]" name="task1" duration-ms="18914" started-at="2017-08-21T03:27:04Z" finished-at="2017-08-21T03:27:22Z">
          <exception class="java.lang.AssertionError">
            <message>
              <![CDATA[Incorrect URL opened! expected [https://www.datalicious.com/] but found [http://www.google.co.in/search?hl=en-IN&source=hp&biw=&bih=&q=Datalicious&gbv=2&oq=Datalicious&gs_l=heirloom-hp.12..0l10.2338.2360.0.4433.11.2.0.0.0.0.173.282.0j2.2.0....0...1.1.34.heirloom-hp..9.2.282.Xw5jxUx_R68]]]>
            </message>
            <full-stacktrace>
              <![CDATA[java.lang.AssertionError: Incorrect URL opened! expected [https://www.datalicious.com/] but found [http://www.google.co.in/search?hl=en-IN&source=hp&biw=&bih=&q=Datalicious&gbv=2&oq=Datalicious&gs_l=heirloom-hp.12..0l10.2338.2360.0.4433.11.2.0.0.0.0.173.282.0j2.2.0....0...1.1.34.heirloom-hp..9.2.282.Xw5jxUx_R68]
	at org.testng.Assert.fail(Assert.java:93)
	at org.testng.Assert.failNotEquals(Assert.java:512)
	at org.testng.Assert.assertEqualsImpl(Assert.java:134)
	at org.testng.Assert.assertEquals(Assert.java:115)
	at org.testng.Assert.assertEquals(Assert.java:189)
	at dataliciousAssignment.NewPhantomJsTest.task1(NewPhantomJsTest.java:125)
	at sun.reflect.NativeMethodAccessorImpl.invoke0(Native Method)
	at sun.reflect.NativeMethodAccessorImpl.invoke(NativeMethodAccessorImpl.java:62)
	at sun.reflect.DelegatingMethodAccessorImpl.invoke(DelegatingMethodAccessorImpl.java:43)
	at java.lang.reflect.Method.invoke(Method.java:498)
	at org.testng.internal.MethodInvocationHelper.invokeMethod(MethodInvocationHelper.java:108)
	at org.testng.internal.Invoker.invokeMethod(Invoker.java:661)
	at org.testng.internal.Invoker.invokeTestMethod(Invoker.java:869)
	at org.testng.internal.Invoker.invokeTestMethods(Invoker.java:1193)
	at org.testng.internal.TestMethodWorker.invokeTestMethods(TestMethodWorker.java:126)
	at org.testng.internal.TestMethodWorker.run(TestMethodWorker.java:109)
	at org.testng.TestRunner.privateRun(TestRunner.java:744)
	at org.testng.TestRunner.run(TestRunner.java:602)
	at org.testng.SuiteRunner.runTest(SuiteRunner.java:380)
	at org.testng.SuiteRunner.runSequentially(SuiteRunner.java:375)
	at org.testng.SuiteRunner.privateRun(SuiteRunner.java:340)
	at org.testng.SuiteRunner.run(SuiteRunner.java:289)
	at org.testng.SuiteRunnerWorker.runSuite(SuiteRunnerWorker.java:52)
	at org.testng.SuiteRunnerWorker.run(SuiteRunnerWorker.java:86)
	at org.testng.TestNG.runSuitesSequentially(TestNG.java:1301)
	at org.testng.TestNG.runSuitesLocally(TestNG.java:1226)
	at org.testng.TestNG.runSuites(TestNG.java:1144)
	at org.testng.TestNG.run(TestNG.java:1115)
	at org.testng.remote.AbstractRemoteTestNG.run(AbstractRemoteTestNG.java:132)
	at org.testng.remote.RemoteTestNG.initAndRun(RemoteTestNG.java:230)
	at org.testng.remote.RemoteTestNG.main(RemoteTestNG.java:76)
]]>
            </full-stacktrace>
          </exception> <!-- java.lang.AssertionError -->
          <reporter-output>
          </reporter-output>
        </test-method> <!-- task1 -->
        <test-method status="SKIP" signature="task2()[pri:0, instance:dataliciousAssignment.NewPhantomJsTest@5383967b]" name="task2" duration-ms="0" started-at="2017-08-21T03:27:22Z" depends-on-methods="dataliciousAssignment.NewPhantomJsTest.task1" finished-at="2017-08-21T03:27:22Z">
          <exception class="java.lang.Throwable">
            <message>
              <![CDATA[Method NewPhantomJsTest.task2()[pri:0, instance:dataliciousAssignment.NewPhantomJsTest@5383967b] depends on not successfully finished methods]]>
            </message>
            <full-stacktrace>
              <![CDATA[java.lang.Throwable: Method NewPhantomJsTest.task2()[pri:0, instance:dataliciousAssignment.NewPhantomJsTest@5383967b] depends on not successfully finished methods
	at org.testng.internal.Invoker.invokeTestMethods(Invoker.java:1084)
	at org.testng.internal.TestMethodWorker.invokeTestMethods(TestMethodWorker.java:126)
	at org.testng.internal.TestMethodWorker.run(TestMethodWorker.java:109)
	at org.testng.TestRunner.privateRun(TestRunner.java:744)
	at org.testng.TestRunner.run(TestRunner.java:602)
	at org.testng.SuiteRunner.runTest(SuiteRunner.java:380)
	at org.testng.SuiteRunner.runSequentially(SuiteRunner.java:375)
	at org.testng.SuiteRunner.privateRun(SuiteRunner.java:340)
	at org.testng.SuiteRunner.run(SuiteRunner.java:289)
	at org.testng.SuiteRunnerWorker.runSuite(SuiteRunnerWorker.java:52)
	at org.testng.SuiteRunnerWorker.run(SuiteRunnerWorker.java:86)
	at org.testng.TestNG.runSuitesSequentially(TestNG.java:1301)
	at org.testng.TestNG.runSuitesLocally(TestNG.java:1226)
	at org.testng.TestNG.runSuites(TestNG.java:1144)
	at org.testng.TestNG.run(TestNG.java:1115)
	at org.testng.remote.AbstractRemoteTestNG.run(AbstractRemoteTestNG.java:132)
	at org.testng.remote.RemoteTestNG.initAndRun(RemoteTestNG.java:230)
	at org.testng.remote.RemoteTestNG.main(RemoteTestNG.java:76)
]]>
            </full-stacktrace>
          </exception> <!-- java.lang.Throwable -->
          <reporter-output>
          </reporter-output>
        </test-method> <!-- task2 -->
        <test-method status="SKIP" signature="task3()[pri:0, instance:dataliciousAssignment.NewPhantomJsTest@5383967b]" name="task3" duration-ms="0" started-at="2017-08-21T03:27:22Z" depends-on-methods="dataliciousAssignment.NewPhantomJsTest.task2" finished-at="2017-08-21T03:27:22Z">
          <exception class="java.lang.Throwable">
            <message>
              <![CDATA[Method NewPhantomJsTest.task3()[pri:0, instance:dataliciousAssignment.NewPhantomJsTest@5383967b] depends on not successfully finished methods]]>
            </message>
            <full-stacktrace>
              <![CDATA[java.lang.Throwable: Method NewPhantomJsTest.task3()[pri:0, instance:dataliciousAssignment.NewPhantomJsTest@5383967b] depends on not successfully finished methods
	at org.testng.internal.Invoker.invokeTestMethods(Invoker.java:1084)
	at org.testng.internal.TestMethodWorker.invokeTestMethods(TestMethodWorker.java:126)
	at org.testng.internal.TestMethodWorker.run(TestMethodWorker.java:109)
	at org.testng.TestRunner.privateRun(TestRunner.java:744)
	at org.testng.TestRunner.run(TestRunner.java:602)
	at org.testng.SuiteRunner.runTest(SuiteRunner.java:380)
	at org.testng.SuiteRunner.runSequentially(SuiteRunner.java:375)
	at org.testng.SuiteRunner.privateRun(SuiteRunner.java:340)
	at org.testng.SuiteRunner.run(SuiteRunner.java:289)
	at org.testng.SuiteRunnerWorker.runSuite(SuiteRunnerWorker.java:52)
	at org.testng.SuiteRunnerWorker.run(SuiteRunnerWorker.java:86)
	at org.testng.TestNG.runSuitesSequentially(TestNG.java:1301)
	at org.testng.TestNG.runSuitesLocally(TestNG.java:1226)
	at org.testng.TestNG.runSuites(TestNG.java:1144)
	at org.testng.TestNG.run(TestNG.java:1115)
	at org.testng.remote.AbstractRemoteTestNG.run(AbstractRemoteTestNG.java:132)
	at org.testng.remote.RemoteTestNG.initAndRun(RemoteTestNG.java:230)
	at org.testng.remote.RemoteTestNG.main(RemoteTestNG.java:76)
]]>
            </full-stacktrace>
          </exception> <!-- java.lang.Throwable -->
          <reporter-output>
          </reporter-output>
        </test-method> <!-- task3 -->
        <test-method status="PASS" signature="afterClass()[pri:0, instance:dataliciousAssignment.NewPhantomJsTest@5383967b]" name="afterClass" is-config="true" duration-ms="1" started-at="2017-08-21T03:27:22Z" finished-at="2017-08-21T03:27:22Z">
          <reporter-output>
          </reporter-output>
        </test-method> <!-- afterClass -->
        <test-method status="PASS" signature="afterTest()[pri:0, instance:dataliciousAssignment.NewPhantomJsTest@5383967b]" name="afterTest" is-config="true" duration-ms="3495" started-at="2017-08-21T03:27:22Z" finished-at="2017-08-21T03:27:26Z">
          <reporter-output>
          </reporter-output>
        </test-method> <!-- afterTest -->
      </class> <!-- dataliciousAssignment.NewPhantomJsTest -->
    </test> <!-- Default test -->
  </suite> <!-- Default suite -->
</testng-results>
